Workbook

Sheet Читать первым
A1: ИЛЛЮСТРАТИВНАЯ ФИНАНСОВАЯ МОДЕЛЬ FOOTUREX UZBEKISTAN (USD тыс.)
A3: Статус: расчётный сценарий на основе допущений. Не является финансовой отчётностью, прогнозом руководства или предложением инвестиций.
A4: Все драйверы на листе «Допущения» требуют подтверждения бизнес-планом и утверждённой финансовой моделью компании.
A5: Выручка игры учитывает только денежные платежи пользователей и рекламу. Внутриигровая валюта (FX Coins) не является выручкой.
A6: Проекты FC FootureX (профессиональный клуб), FootureX Stadium и FootureX City НЕ включены: требуются отдельные ТЭО, земля, разрешения и проектное финансирование.
A7: Льготы резидентов IT Park не учтены (консервативно): налог на прибыль 15%. Применимость льгот требует юридического подтверждения.
A8: Сценарии: пессимистичный = 70% объёмных драйверов; оптимистичный = 130%. Цены, ставки и фиксированные OPEX не масштабируются.
A9: Синие ячейки — вводимые допущения. Лист «P&L и денежный поток» считается формулами из допущений (базовый сценарий).

Sheet Допущения
A1: Драйвер | B1: Ед. | C1: Год 1 | D1: Год 2 | E1: Год 3 | F1: Год 4 | G1: Год 5
A2: FootureX Technologies — IT-услуги
A3: Оплачиваемые специалисты (FTE) | B3: чел. | C3: 8 | D3: 16 | E3: 28 | F3: 40 | G3: 55
A4: Рабочих часов на FTE в год | B4: ч | C4: 1760 | D4: 1760 | E4: 1760 | F4: 1760 | G4: 1760
A5: Загрузка (utilization) | B5: % | C5: 0.7 | D5: 0.75 | E5: 0.78 | F5: 0.8 | G5: 0.8
A6: Средняя ставка | B6: $/ч | C6: 22 | D6: 24 | E6: 26 | F6: 28 | G6: 30
A7: Полная стоимость FTE | B7: $ тыс./год | C7: 14 | D7: 15 | E7: 16.5 | F7: 18 | G7: 19.5
A8: FootureX AI — проекты и SaaS
A9: AI-проекты (внедрения агентов) | B9: шт. | C9: 4 | D9: 8 | E9: 12 | F9: 15 | G9: 18
A10: Средний чек проекта | B10: $ тыс. | C10: 15 | D10: 22 | E10: 28 | F10: 32 | G10: 35
A11: Себестоимость проектов | B11: % выручки | C11: 0.55 | D11: 0.55 | E11: 0.52 | F11: 0.5 | G11: 0.5
A12: Платящие SaaS-клиенты на конец года | B12: шт. | C12: 10 | D12: 45 | E12: 120 | F12: 240 | G12: 400
A13: ARPA (средний чек в месяц) | B13: $ | C13: 120 | D13: 140 | E13: 160 | F13: 180 | G13: 200
A14: Себестоимость SaaS (инференс, облако, поддержка) | B14: % выручки | C14: 0.32 | D14: 0.3 | E14: 0.28 | F14: 0.27 | G14: 0.26
A15: Отток клиентов в месяц | B15: % | C15: 0.03 | D15: 0.028 | E15: 0.025 | F15: 0.022 | G15: 0.02
A16: CAC SaaS | B16: $ | C16: 700 | D16: 800 | E16: 900 | F16: 950 | G16: 1000
A17: FootureX Game — Telegram Web App (только денежная выручка)
A18: Средний MAU | B18: тыс. | C18: 40 | D18: 150 | E18: 350 | F18: 600 | G18: 900
A19: Месяцев коммерческой эксплуатации | B19: мес. | C19: 6 | D19: 12 | E19: 12 | F19: 12 | G19: 12
A20: Доля платящих | B20: % | C20: 0.015 | D20: 0.02 | E20: 0.025 | F20: 0.028 | G20: 0.03
A21: ARPPU в месяц | B21: $ | C21: 6 | D21: 7 | E21: 8 | F21: 8.5 | G21: 9
A22: Рекламная выручка на MAU в месяц | B22: $ | C22: 0.03 | D22: 0.03 | E22: 0.03 | F22: 0.03 | G22: 0.03
A23: Комиссии платформ и платёжных провайдеров | B23: % IAP | C23: 0.3 | D23: 0.3 | E23: 0.3 | F23: 0.3 | G23: 0.3
A24: Хостинг и LiveOps-инфраструктура | B24: % выручки | C24: 0.08 | D24: 0.06 | E24: 0.05 | F24: 0.05 | G24: 0.05
A25: Маркетинг и привлечение игроков (UA) | B25: $ тыс. | C25: 60 | D25: 250 | E25: 450 | F25: 650 | G25: 850
A26: Новые игроки за год | B26: тыс. | C26: 120 | D26: 400 | E26: 700 | F26: 1000 | G26: 1300
A27: FootureX Game Development — заказная разработка
A28: Выручка заказной разработки игр | B28: $ тыс. | C28: 0 | D28: 120 | E28: 300 | F28: 450 | G28: 600
A29: Себестоимость заказной разработки | B29: % выручки | C29: 0.55 | D29: 0.55 | E29: 0.55 | F29: 0.55 | G29: 0.55
A30: FootureX Game Dev Academy
A31: Слушатели в год | B31: чел. | C31: 60 | D31: 180 | E31: 360 | F31: 540 | G31: 720
A32: Средняя стоимость обучения | B32: $ | C32: 700 | D32: 750 | E32: 800 | F32: 850 | G32: 900
A33: Себестоимость обучения (преподаватели, контент) | B33: % выручки | C33: 0.48 | D33: 0.46 | E33: 0.45 | F33: 0.45 | G33: 0.45
A34: FootureX Game Community & Esports
A35: Спонсорство, билеты, медиа | B35: $ тыс. | C35: 0 | D35: 40 | E35: 120 | F35: 250 | G35: 400
A36: Прямые затраты мероприятий и призовые | B36: % выручки | C36: 0.65 | D36: 0.65 | E36: 0.62 | F36: 0.6 | G36: 0.58
A37: FootureX Football Academy — пилот (FC, стадион, City вне модели)
A38: Выручка детско-юношеских программ | B38: $ тыс. | C38: 0 | D38: 0 | E38: 0 | F38: 80 | G38: 160
A39: Операционные затраты академии | B39: $ тыс. | C39: 0 | D39: 0 | E39: 0 | F39: 250 | G39: 350
A40: Операционные расходы (OPEX)
...

Sheet P&L и денежный поток
A1: Показатель (USD тыс.) | C1: Год 1 | D1: Год 2 | E1: Год 3 | F1: Год 4 | G1: Год 5
A2: Выручка: IT-услуги | C2: ='Допущения'!C3*'Допущения'!C4*'Допущения'!C5*'Допущения'!C6/1000 | D2: ='Допущения'!D3*'Допущения'!D4*'Допущения'!D5*'Допущения'!D6/1000 | E2: ='Допущения'!E3*'Допущения'!E4*'Допущения'!E5*'Допущения'!E6/1000 | F2: ='Допущения'!F3*'Допущения'!F4*'Допущения'!F5*'Допущения'!F6/1000 | G2: ='Допущения'!G3*'Допущения'!G4*'Допущения'!G5*'Допущения'!G6/1000
A3: Выручка: AI-проекты | C3: ='Допущения'!C9*'Допущения'!C10 | D3: ='Допущения'!D9*'Допущения'!D10 | E3: ='Допущения'!E9*'Допущения'!E10 | F3: ='Допущения'!F9*'Допущения'!F10 | G3: ='Допущения'!G9*'Допущения'!G10
A4: Выручка: AI SaaS | C4: =((0+'Допущения'!C12)/2)*'Допущения'!C13*12/1000 | D4: =(('Допущения'!C12+'Допущения'!D12)/2)*'Допущения'!D13*12/1000 | E4: =(('Допущения'!D12+'Допущения'!E12)/2)*'Допущения'!E13*12/1000 | F4: =(('Допущения'!E12+'Допущения'!F12)/2)*'Допущения'!F13*12/1000 | G4: =(('Допущения'!F12+'Допущения'!G12)/2)*'Допущения'!G13*12/1000
A5: Выручка: игра — покупки (IAP) | C5: ='Допущения'!C18*1000*'Допущения'!C20*'Допущения'!C21*'Допущения'!C19/1000 | D5: ='Допущения'!D18*1000*'Допущения'!D20*'Допущения'!D21*'Допущения'!D19/1000 | E5: ='Допущения'!E18*1000*'Допущения'!E20*'Допущения'!E21*'Допущения'!E19/1000 | F5: ='Допущения'!F18*1000*'Допущения'!F20*'Допущения'!F21*'Допущения'!F19/1000 | G5: ='Допущения'!G18*1000*'Допущения'!G20*'Допущения'!G21*'Допущения'!G19/1000
A6: Выручка: игра — реклама | C6: ='Допущения'!C18*1000*'Допущения'!C22*'Допущения'!C19/1000 | D6: ='Допущения'!D18*1000*'Допущения'!D22*'Допущения'!D19/1000 | E6: ='Допущения'!E18*1000*'Допущения'!E22*'Допущения'!E19/1000 | F6: ='Допущения'!F18*1000*'Допущения'!F22*'Допущения'!F19/1000 | G6: ='Допущения'!G18*1000*'Допущения'!G22*'Допущения'!G19/1000
A7: Выручка: заказная разработка игр | C7: ='Допущения'!C28 | D7: ='Допущения'!D28 | E7: ='Допущения'!E28 | F7: ='Допущения'!F28 | G7: ='Допущения'!G28
A8: Выручка: Game Dev Academy | C8: ='Допущения'!C31*'Допущения'!C32/1000 | D8: ='Допущения'!D31*'Допущения'!D32/1000 | E8: ='Допущения'!E31*'Допущения'!E32/1000 | F8: ='Допущения'!F31*'Допущения'!F32/1000 | G8: ='Допущения'!G31*'Допущения'!G32/1000
A9: Выручка: Community & Esports | C9: ='Допущения'!C35 | D9: ='Допущения'!D35 | E9: ='Допущения'!E35 | F9: ='Допущения'!F35 | G9: ='Допущения'!G35
A10: Выручка: Football Academy (пилот) | C10: ='Допущения'!C38 | D10: ='Допущения'!D38 | E10: ='Допущения'!E38 | F10: ='Допущения'!F38 | G10: ='Допущения'!G38
A11: ВЫРУЧКА | C11: =SUM(C2:C10) | D11: =SUM(D2:D10) | E11: =SUM(E2:E10) | F11: =SUM(F2:F10) | G11: =SUM(G2:G10)
A12: Себестоимость (прямые затраты) | C12: ='Допущения'!C3*'Допущения'!C7+C3*'Допущения'!C11+C4*'Допущения'!C14+C5*'Допущения'!C23+(C5+C6)*'Допущения'!C24+C7*'Допущения'!C29+C8*'Допущения'!C33+C9*'Допущения'!C36+'Допущения'!C39 | D12: ='Допущения'!D3*'Допущения'!D7+D3*'Допущения'!D11+D4*'Допущения'!D14+D5*'Допущения'!D23+(D5+D6)*'Допущения'!D24+D7*'Допущения'!D29+D8*'Допущения'!D33+D9*'Допущения'!D36+'Допущения'!D39 | E12: ='Допущения'!E3*'Допущения'!E7+E3*'Допущения'!E11+E4*'Допущения'!E14+E5*'Допущения'!E23+(E5+E6)*'Допущения'!E24+E7*'Допущения'!E29+E8*'Допущения'!E33+E9*'Допущения'!E36+'Допущения'!E39 | F12: ='Допущения'!F3*'Допущения'!F7+F3*'Допущения'!F11+F4*'Допущения'!F14+F5*'Допущения'!F23+(F5+F6)*'Допущения'!F24+F7*'Допущения'!F29+F8*'Допущения'!F33+F9*'Допущения'!F36+'Допущения'!F39 | G12: ='Допущения'!G3*'Допущения'!G7+G3*'Допущения'!G11+G4*'Допущения'!G14+G5*'Допущения'!G23+(G5+G6)*'Допущения'!G24+G7*'Допущения'!G29+G8*'Допущения'!G33+G9*'Допущения'!G36+'Допущения'!G39
A13: ВАЛОВАЯ ПРИБЫЛЬ | C13: =C11-C12 | D13: =D11-D12 | E13: =E11-E12 | F13: =F11-F12 | G13: =G11-G12
A14: Валовая маржа, % | C14: =IF(C11=0,0,C13/C11*100) | D14: =IF(D11=0,0,D13/D11*100) | E14: =IF(E11=0,0,E13/E11*100) | F14: =IF(F11=0,0,F13/F11*100) | G14: =IF(G11=0,0,G13/G11*100)
A15: OPEX (включая UA игры) | C15: ='Допущения'!C41+'Допущения'!C42+'Допущения'!C43+'Допущения'!C44+'Допущения'!C45+'Допущения'!C25 | D15: ='Допущения'!D41+'Допущения'!D42+'Допущения'!D43+'Допущения'!D44+'Допущения'!D45+'Допущения'!D25 | E15: ='Допущения'!E41+'Допущения'!E42+'Допущения'!E43+'Допущения'!E44+'Допущения'!E45+'Допущения'!E25 | F15: ='Допущения'!F41+'Допущения'!F42+'Допущения'!F43+'Допущения'!F44+'Допущения'!F45+'Допущения'!F25 | G15: ='Допущения'!G41+'Допущения'!G42+'Допущения'!G43+'Допущения'!G44+'Допущения'!G45+'Допущения'!G25
A16: EBITDA | C16: =C13-C15 | D16: =D13-D15 | E16: =E13-E15 | F16: =F13-F15 | G16: =G13-G15
A17: CAPEX | C17: ='Допущения'!C47+'Допущения'!C48+'Допущения'!C49+'Допущения'!C50 | D17: ='Допущения'!D47+'Допущения'!D48+'Допущения'!D49+'Допущения'!D50 | E17: ='Допущения'!E47+'Допущения'!E48+'Допущения'!E49+'Допущения'!E50 | F17: ='Допущения'!F47+'Допущения'!F48+'Допущения'!F49+'Допущения'!F50 | G17: ='Допущения'!G47+'Допущения'!G48+'Допущения'!G49+'Допущения'!G50
A18: Амортизация | C18: =C17/'Допущения'!C51 | D18: =C17/'Допущения'!C51+D17/'Допущения'!D51 | E18: =C17/'Допущения'!C51+D17/'Допущения'!D51+E17/'Допущения'!E51 | F18: =C17/'Допущения'!C51+D17/'Допущения'!D51+E17/'Допущения'!E51+F17/'Допущения'!F51 | G18: =D17/'Допущения'!D51+E17/'Допущения'!E51+F17/'Допущения'!F51+G17/'Допущения'!G51
A19: EBIT | C19: =C16-C18 | D19: =D16-D18 | E19: =E16-E18 | F19: =F16-F18 | G19: =G16-G18
A20: Накопленный EBIT (для переноса убытков) | C20: =C19 | D20: =C20+D19 | E20: =D20+E19 | F20: =E20+F19 | G20: =F20+G19
A21: Налог на прибыль | C21: =MAX(0,MIN(C19,C20))*'Допущения'!C53 | D21: =MAX(0,MIN(D19,D20))*'Допущения'!D53 | E21: =MAX(0,MIN(E19,E20))*'Допущения'!E53 | F21: =MAX(0,MIN(F19,F20))*'Допущения'!F53 | G21: =MAX(0,MIN(G19,G20))*'Допущения'!G53
A22: ЧИСТАЯ ПРИБЫЛЬ | C22: =C19-C21 | D22: =D19-D21 | E22: =E19-E21 | F22: =F19-F21 | G22: =G19-G21
A23: Изменение оборотного капитала | C23: =(C11-0)*'Допущения'!C52 | D23: =(D11-C11)*'Допущения'!D52 | E23: =(E11-D11)*'Допущения'!E52 | F23: =(F11-E11)*'Допущения'!F52 | G23: =(G11-F11)*'Допущения'!G52
A24: ОПЕРАЦИОННЫЙ ДЕНЕЖНЫЙ ПОТОК | C24: =C22+C18-C23 | D24: =D22+D18-D23 | E24: =E22+E18-E23 | F24: =F22+F18-F23 | G24: =G22+G18-G23
A25: СВОБОДНЫЙ ДЕНЕЖНЫЙ ПОТОК (FCF) | C25: =C24-C17 | D25: =D24-D17 | E25: =E24-E17 | F25: =F24-F17 | G25: =G24-G17
A26: Накопленный FCF | C26: =C25 | D26: =C26+D25 | E26: =D26+E25 | F26: =E26+F25 | G26: =F26+G25
A28: Пиковая потребность в финансировании (до резерва) | C28: =-MIN(0,C26:G26)
A29: Резерв на непредвиденные расходы | C29: 0.25
A30: Потребность в капитале с резервом (округл. до 50) | C30: =CEILING(C28*(1+C29),50)

Sheet Сценарии
A1: Показатель (USD тыс.) | B1: Пессимистичный | C1: Базовый | D1: Оптимистичный
A2: Выручка, Год 5 | B2: 6138.4 | C2: 8769.2 | D2: 11400
A3: EBITDA, Год 5 | B3: 501.6 | C3: 1961.6 | D3: 3421.6
A4: Чистая прибыль, Год 5 | B4: 76.6 | C4: 1398.7 | D4: 2547.1
A5: Накопленный FCF за 5 лет | B5: -3406.4 | C5: -687.7 | D5: 1708.9
A6: Год выхода EBITDA в плюс | B6: Год 5 | C6: Год 3 | D6: Год 3
A7: Окупаемость (накопленный FCF ≥ 0) | B7: > 5 лет | C7: > 5 лет | D7: Год 5
A8: Потребность в капитале (с резервом 25%) | B8: 4300 | C8: 2200 | D8: 1400
A9: Значения сценариев рассчитаны скриптом build/finmodel.js; базовый сценарий пересчитывается формулами на листе P&L.
